2019-06-25 17:42:08,487 ERROR: Exception on /reset_password_request [POST] [in /home/how_r_u/.local/lib/python3.6/site-packages/flask/app.py:1780]
Traceback (most recent call last):
  File "/home/how_r_u/.local/lib/python3.6/site-packages/flask/app.py", line 2311, in wsgi_app
    response = self.full_dispatch_request()
  File "/home/how_r_u/.local/lib/python3.6/site-packages/flask/app.py", line 1834, in full_dispatch_request
    rv = self.handle_user_exception(e)
  File "/home/how_r_u/.local/lib/python3.6/site-packages/flask/app.py", line 1737, in handle_user_exception
    reraise(exc_type, exc_value, tb)
  File "/home/how_r_u/.local/lib/python3.6/site-packages/flask/_compat.py", line 36, in reraise
    raise value
  File "/home/how_r_u/.local/lib/python3.6/site-packages/flask/app.py", line 1832, in full_dispatch_request
    rv = self.dispatch_request()
  File "/home/how_r_u/.local/lib/python3.6/site-packages/flask/app.py", line 1818, in dispatch_request
    return self.view_functions[rule.endpoint](**req.view_args)
  File "/home/how_r_u/Desktop/mega_book/app/routes.py", line 167, in reset_password_request
    send_password_reset_email(user)
  File "/home/how_r_u/Desktop/mega_book/app/email.py", line 14, in send_password_reset_email
    html_body = render_template('email/reset_password.html', user=user, token=token))
  File "/home/how_r_u/Desktop/mega_book/app/email.py", line 5, in send_email
    msg = Message(subject, sender=sender, recipients=recipients)
NameError: name 'Message' is not defined
2019-06-25 17:42:36,060 INFO: Microblog startup [in /home/how_r_u/Desktop/mega_book/app/__init__.py:56]
2019-06-25 17:42:40,811 ERROR: Exception on /reset_password_request [POST] [in /home/how_r_u/.local/lib/python3.6/site-packages/flask/app.py:1780]
Traceback (most recent call last):
  File "/home/how_r_u/.local/lib/python3.6/site-packages/flask/app.py", line 2311, in wsgi_app
    response = self.full_dispatch_request()
  File "/home/how_r_u/.local/lib/python3.6/site-packages/flask/app.py", line 1834, in full_dispatch_request
    rv = self.handle_user_exception(e)
  File "/home/how_r_u/.local/lib/python3.6/site-packages/flask/app.py", line 1737, in handle_user_exception
    reraise(exc_type, exc_value, tb)
  File "/home/how_r_u/.local/lib/python3.6/site-packages/flask/_compat.py", line 36, in reraise
    raise value
  File "/home/how_r_u/.local/lib/python3.6/site-packages/flask/app.py", line 1832, in full_dispatch_request
    rv = self.dispatch_request()
  File "/home/how_r_u/.local/lib/python3.6/site-packages/flask/app.py", line 1818, in dispatch_request
    return self.view_functions[rule.endpoint](**req.view_args)
  File "/home/how_r_u/Desktop/mega_book/app/routes.py", line 167, in reset_password_request
    send_password_reset_email(user)
  File "/home/how_r_u/Desktop/mega_book/app/email.py", line 15, in send_password_reset_email
    html_body = render_template('email/reset_password.html', user=user, token=token))
  File "/home/how_r_u/Desktop/mega_book/app/email.py", line 9, in send_email
    mail.send(msg)
NameError: name 'mail' is not defined
2019-06-25 17:43:09,957 INFO: Microblog startup [in /home/how_r_u/Desktop/mega_book/app/__init__.py:56]
2019-06-25 17:43:15,049 ERROR: Exception on /reset_password_request [POST] [in /home/how_r_u/.local/lib/python3.6/site-packages/flask/app.py:1780]
Traceback (most recent call last):
  File "/home/how_r_u/.local/lib/python3.6/site-packages/flask/app.py", line 2311, in wsgi_app
    response = self.full_dispatch_request()
  File "/home/how_r_u/.local/lib/python3.6/site-packages/flask/app.py", line 1834, in full_dispatch_request
    rv = self.handle_user_exception(e)
  File "/home/how_r_u/.local/lib/python3.6/site-packages/flask/app.py", line 1737, in handle_user_exception
    reraise(exc_type, exc_value, tb)
  File "/home/how_r_u/.local/lib/python3.6/site-packages/flask/_compat.py", line 36, in reraise
    raise value
  File "/home/how_r_u/.local/lib/python3.6/site-packages/flask/app.py", line 1832, in full_dispatch_request
    rv = self.dispatch_request()
  File "/home/how_r_u/.local/lib/python3.6/site-packages/flask/app.py", line 1818, in dispatch_request
    return self.view_functions[rule.endpoint](**req.view_args)
  File "/home/how_r_u/Desktop/mega_book/app/routes.py", line 167, in reset_password_request
    send_password_reset_email(user)
  File "/home/how_r_u/Desktop/mega_book/app/email.py", line 13, in send_password_reset_email
    send_email("[Microblog] Reset your password", sender=app.config["ADMINS"][0], recipients=[user.email],
NameError: name 'app' is not defined
2019-06-25 17:43:25,643 INFO: Microblog startup [in /home/how_r_u/Desktop/mega_book/app/__init__.py:56]
2019-06-25 17:44:58,623 ERROR: Exception on /reset_password/eyJ0eXAiOiJKV1QiLCJhbGciOiJIUzI1NiJ9.eyJyZXNldF9wYXNzd29yZCI6OSwiZXhwIjoxNTYxNDc0NDExLjkyMzI5MDd9.WpvgV29EpFIMhclabKm6Fyu54W5WMKfNiES7FRoAfVk [GET] [in /home/how_r_u/.local/lib/python3.6/site-packages/flask/app.py:1780]
Traceback (most recent call last):
  File "/home/how_r_u/.local/lib/python3.6/site-packages/flask/app.py", line 2311, in wsgi_app
    response = self.full_dispatch_request()
  File "/home/how_r_u/.local/lib/python3.6/site-packages/flask/app.py", line 1834, in full_dispatch_request
    rv = self.handle_user_exception(e)
  File "/home/how_r_u/.local/lib/python3.6/site-packages/flask/app.py", line 1737, in handle_user_exception
    reraise(exc_type, exc_value, tb)
  File "/home/how_r_u/.local/lib/python3.6/site-packages/flask/_compat.py", line 36, in reraise
    raise value
  File "/home/how_r_u/.local/lib/python3.6/site-packages/flask/app.py", line 1832, in full_dispatch_request
    rv = self.dispatch_request()
  File "/home/how_r_u/.local/lib/python3.6/site-packages/flask/app.py", line 1818, in dispatch_request
    return self.view_functions[rule.endpoint](**req.view_args)
  File "/home/how_r_u/Desktop/mega_book/app/routes.py", line 176, in reset_password
    user = User.verify_reset_password_token(token)
  File "/home/how_r_u/Desktop/mega_book/app/models.py", line 90, in verify_reset_password_token
    return User.query.ger(id)
AttributeError: 'BaseQuery' object has no attribute 'ger'
2019-06-25 17:45:27,900 INFO: Microblog startup [in /home/how_r_u/Desktop/mega_book/app/__init__.py:56]
2019-06-25 17:45:31,496 ERROR: Exception on /reset_password/eyJ0eXAiOiJKV1QiLCJhbGciOiJIUzI1NiJ9.eyJyZXNldF9wYXNzd29yZCI6OSwiZXhwIjoxNTYxNDc0NDExLjkyMzI5MDd9.WpvgV29EpFIMhclabKm6Fyu54W5WMKfNiES7FRoAfVk [GET] [in /home/how_r_u/.local/lib/python3.6/site-packages/flask/app.py:1780]
Traceback (most recent call last):
  File "/home/how_r_u/.local/lib/python3.6/site-packages/flask/app.py", line 2311, in wsgi_app
    response = self.full_dispatch_request()
  File "/home/how_r_u/.local/lib/python3.6/site-packages/flask/app.py", line 1834, in full_dispatch_request
    rv = self.handle_user_exception(e)
  File "/home/how_r_u/.local/lib/python3.6/site-packages/flask/app.py", line 1737, in handle_user_exception
    reraise(exc_type, exc_value, tb)
  File "/home/how_r_u/.local/lib/python3.6/site-packages/flask/_compat.py", line 36, in reraise
    raise value
  File "/home/how_r_u/.local/lib/python3.6/site-packages/flask/app.py", line 1832, in full_dispatch_request
    rv = self.dispatch_request()
  File "/home/how_r_u/.local/lib/python3.6/site-packages/flask/app.py", line 1818, in dispatch_request
    return self.view_functions[rule.endpoint](**req.view_args)
  File "/home/how_r_u/Desktop/mega_book/app/routes.py", line 180, in reset_password
    form = ResetPasswordForm()
  File "/home/how_r_u/.local/lib/python3.6/site-packages/wtforms/form.py", line 212, in __call__
    return type.__call__(cls, *args, **kwargs)
  File "/home/how_r_u/.local/lib/python3.6/site-packages/flask_wtf/form.py", line 88, in __init__
    super(FlaskForm, self).__init__(formdata=formdata, **kwargs)
  File "/home/how_r_u/.local/lib/python3.6/site-packages/wtforms/form.py", line 272, in __init__
    super(Form, self).__init__(self._unbound_fields, meta=meta_obj, prefix=prefix)
  File "/home/how_r_u/.local/lib/python3.6/site-packages/wtforms/form.py", line 52, in __init__
    field = meta.bind_field(self, unbound_field, options)
  File "/home/how_r_u/.local/lib/python3.6/site-packages/wtforms/meta.py", line 27, in bind_field
    return unbound_field.bind(form=form, **options)
  File "/home/how_r_u/.local/lib/python3.6/site-packages/wtforms/fields/core.py", line 353, in bind
    return self.field_class(*self.args, **kw)
TypeError: __init__() got an unexpected keyword argument 'validatord'
2019-06-25 17:45:49,500 INFO: Microblog startup [in /home/how_r_u/Desktop/mega_book/app/__init__.py:56]
2019-06-25 17:53:25,733 INFO: Microblog startup [in /home/how_r_u/Desktop/mega_book/app/__init__.py:56]
2019-06-25 17:55:58,607 INFO: Microblog startup [in /home/how_r_u/Desktop/mega_book/app/__init__.py:56]
2019-06-25 17:57:18,410 INFO: Microblog startup [in /home/how_r_u/Desktop/mega_book/app/__init__.py:56]
2019-07-03 10:29:47,691 INFO: Microblog startup [in /Users/lshanaha/Desktop/mega_book/app/__init__.py:58]
2019-07-03 10:31:11,420 INFO: Microblog startup [in /Users/lshanaha/Desktop/mega_book/app/__init__.py:58]
2019-07-03 10:32:15,971 INFO: Microblog startup [in /Users/lshanaha/Desktop/mega_book/app/__init__.py:58]
2019-07-03 10:32:59,534 INFO: Microblog startup [in /Users/lshanaha/Desktop/mega_book/app/__init__.py:58]
2019-07-03 10:42:14,869 INFO: Microblog startup [in /Users/lshanaha/Desktop/mega_book/app/__init__.py:58]
2019-07-03 10:42:38,213 INFO: Microblog startup [in /Users/lshanaha/Desktop/mega_book/app/__init__.py:58]
2019-07-03 10:43:09,794 INFO: Microblog startup [in /Users/lshanaha/Desktop/mega_book/app/__init__.py:58]
2019-07-03 11:07:26,378 INFO: Microblog startup [in /Users/lshanaha/Desktop/mega_book/app/__init__.py:58]
2019-07-03 11:10:23,734 INFO: Microblog startup [in /Users/lshanaha/Desktop/mega_book/app/__init__.py:58]
2019-07-03 11:10:53,822 INFO: Microblog startup [in /Users/lshanaha/Desktop/mega_book/app/__init__.py:58]
2019-07-03 11:11:53,377 INFO: Microblog startup [in /Users/lshanaha/Desktop/mega_book/app/__init__.py:58]
