2019-06-25 14:21:10,183 INFO: Microblog startup [in /home/how_r_u/Desktop/mega_book/app/__init__.py:53]
2019-06-25 14:22:28,410 INFO: Microblog startup [in /home/how_r_u/Desktop/mega_book/app/__init__.py:53]
2019-06-25 14:22:52,817 INFO: Microblog startup [in /home/how_r_u/Desktop/mega_book/app/__init__.py:53]
2019-06-25 14:24:21,581 INFO: Microblog startup [in /home/how_r_u/Desktop/mega_book/app/__init__.py:53]
2019-06-25 14:26:33,076 INFO: Microblog startup [in /home/how_r_u/Desktop/mega_book/app/__init__.py:53]
2019-06-25 14:26:34,606 ERROR: Exception on /user/pass [GET] [in /home/how_r_u/.local/lib/python3.6/site-packages/flask/app.py:1761]
Traceback (most recent call last):
  File "/home/how_r_u/.local/lib/python3.6/site-packages/flask/app.py", line 2292, in wsgi_app
    response = self.full_dispatch_request()
  File "/home/how_r_u/.local/lib/python3.6/site-packages/flask/app.py", line 1815, in full_dispatch_request
    rv = self.handle_user_exception(e)
  File "/home/how_r_u/.local/lib/python3.6/site-packages/flask/app.py", line 1718, in handle_user_exception
    reraise(exc_type, exc_value, tb)
  File "/home/how_r_u/.local/lib/python3.6/site-packages/flask/_compat.py", line 35, in reraise
    raise value
  File "/home/how_r_u/.local/lib/python3.6/site-packages/flask/app.py", line 1813, in full_dispatch_request
    rv = self.dispatch_request()
  File "/home/how_r_u/.local/lib/python3.6/site-packages/flask/app.py", line 1799, in dispatch_request
    return self.view_functions[rule.endpoint](**req.view_args)
  File "/home/how_r_u/.local/lib/python3.6/site-packages/flask_login/utils.py", line 261, in decorated_view
    return func(*args, **kwargs)
  File "/home/how_r_u/Desktop/mega_book/app/routes.py", line 87, in user
    return render_template("user.html", user=user, posts=posts)
  File "/home/how_r_u/.local/lib/python3.6/site-packages/flask/templating.py", line 135, in render_template
    context, ctx.app)
  File "/home/how_r_u/.local/lib/python3.6/site-packages/flask/templating.py", line 117, in _render
    rv = template.render(context)
  File "/home/how_r_u/.local/lib/python3.6/site-packages/jinja2/asyncsupport.py", line 76, in render
    return original_render(self, *args, **kwargs)
  File "/home/how_r_u/.local/lib/python3.6/site-packages/jinja2/environment.py", line 1008, in render
    return self.environment.handle_exception(exc_info, True)
  File "/home/how_r_u/.local/lib/python3.6/site-packages/jinja2/environment.py", line 780, in handle_exception
    reraise(exc_type, exc_value, tb)
  File "/home/how_r_u/.local/lib/python3.6/site-packages/jinja2/_compat.py", line 37, in reraise
    raise value.with_traceback(tb)
  File "/home/how_r_u/Desktop/mega_book/app/templates/user.html", line 1, in top-level template code
    {% extends "base.html" %}
  File "/home/how_r_u/Desktop/mega_book/app/templates/base.html", line 33, in top-level template code
    {% block content %}
  File "/home/how_r_u/Desktop/mega_book/app/templates/user.html", line 24, in block "content"
    {% for post in posts %}
TypeError: 'Pagination' object is not iterable
2019-06-25 14:26:48,101 INFO: Microblog startup [in /home/how_r_u/Desktop/mega_book/app/__init__.py:53]
2019-06-25 14:27:33,133 INFO: Microblog startup [in /home/how_r_u/Desktop/mega_book/app/__init__.py:53]
2019-06-25 14:54:20,747 INFO: Microblog startup [in /home/how_r_u/Desktop/mega_book/app/__init__.py:53]
2019-06-25 14:56:03,122 INFO: Microblog startup [in /home/how_r_u/Desktop/mega_book/app/__init__.py:53]
2019-06-25 14:56:19,139 INFO: Microblog startup [in /home/how_r_u/Desktop/mega_book/app/__init__.py:53]
2019-06-25 14:58:00,263 INFO: Microblog startup [in /home/how_r_u/Desktop/mega_book/app/__init__.py:53]
2019-06-25 14:58:23,175 INFO: Microblog startup [in /home/how_r_u/Desktop/mega_book/app/__init__.py:53]
2019-06-25 14:58:24,521 ERROR: Exception on /explore [GET] [in /home/how_r_u/.local/lib/python3.6/site-packages/flask/app.py:1761]
Traceback (most recent call last):
  File "/home/how_r_u/.local/lib/python3.6/site-packages/flask/app.py", line 2292, in wsgi_app
    response = self.full_dispatch_request()
  File "/home/how_r_u/.local/lib/python3.6/site-packages/flask/app.py", line 1815, in full_dispatch_request
    rv = self.handle_user_exception(e)
  File "/home/how_r_u/.local/lib/python3.6/site-packages/flask/app.py", line 1718, in handle_user_exception
    reraise(exc_type, exc_value, tb)
  File "/home/how_r_u/.local/lib/python3.6/site-packages/flask/_compat.py", line 35, in reraise
    raise value
  File "/home/how_r_u/.local/lib/python3.6/site-packages/flask/app.py", line 1813, in full_dispatch_request
    rv = self.dispatch_request()
  File "/home/how_r_u/.local/lib/python3.6/site-packages/flask/app.py", line 1799, in dispatch_request
    return self.view_functions[rule.endpoint](**req.view_args)
  File "/home/how_r_u/.local/lib/python3.6/site-packages/flask_login/utils.py", line 261, in decorated_view
    return func(*args, **kwargs)
  File "/home/how_r_u/Desktop/mega_book/app/routes.py", line 153, in explore
    return render_template('index.html', title='Home', form=form,
NameError: name 'form' is not defined
2019-06-25 14:58:39,597 INFO: Microblog startup [in /home/how_r_u/Desktop/mega_book/app/__init__.py:53]
2019-06-25 15:06:45,392 INFO: Microblog startup [in /home/how_r_u/Desktop/mega_book/app/__init__.py:53]
2019-06-25 15:06:46,525 ERROR: Exception on /user/pass [GET] [in /home/how_r_u/.local/lib/python3.6/site-packages/flask/app.py:1761]
Traceback (most recent call last):
  File "/home/how_r_u/.local/lib/python3.6/site-packages/flask/app.py", line 2292, in wsgi_app
    response = self.full_dispatch_request()
  File "/home/how_r_u/.local/lib/python3.6/site-packages/flask/app.py", line 1815, in full_dispatch_request
    rv = self.handle_user_exception(e)
  File "/home/how_r_u/.local/lib/python3.6/site-packages/flask/app.py", line 1718, in handle_user_exception
    reraise(exc_type, exc_value, tb)
  File "/home/how_r_u/.local/lib/python3.6/site-packages/flask/_compat.py", line 35, in reraise
    raise value
  File "/home/how_r_u/.local/lib/python3.6/site-packages/flask/app.py", line 1813, in full_dispatch_request
    rv = self.dispatch_request()
  File "/home/how_r_u/.local/lib/python3.6/site-packages/flask/app.py", line 1799, in dispatch_request
    return self.view_functions[rule.endpoint](**req.view_args)
  File "/home/how_r_u/.local/lib/python3.6/site-packages/flask_login/utils.py", line 261, in decorated_view
    return func(*args, **kwargs)
  File "/home/how_r_u/Desktop/mega_book/app/routes.py", line 90, in user
    next_url = url_for("user", page=posts.next_num) if posts.has_next else None
  File "/home/how_r_u/.local/lib/python3.6/site-packages/flask/helpers.py", line 356, in url_for
    return appctx.app.handle_url_build_error(error, endpoint, values)
  File "/home/how_r_u/.local/lib/python3.6/site-packages/flask/app.py", line 2061, in handle_url_build_error
    reraise(exc_type, exc_value, tb)
  File "/home/how_r_u/.local/lib/python3.6/site-packages/flask/_compat.py", line 35, in reraise
    raise value
  File "/home/how_r_u/.local/lib/python3.6/site-packages/flask/helpers.py", line 345, in url_for
    force_external=external)
  File "/home/how_r_u/.local/lib/python3.6/site-packages/werkzeug/routing.py", line 1776, in build
    raise BuildError(endpoint, values, method, self)
werkzeug.routing.BuildError: Could not build url for endpoint 'user' with values ['page']. Did you forget to specify values ['username']?
2019-06-25 15:07:14,120 INFO: Microblog startup [in /home/how_r_u/Desktop/mega_book/app/__init__.py:53]
2019-06-25 15:07:15,500 ERROR: Exception on /user/pass [GET] [in /home/how_r_u/.local/lib/python3.6/site-packages/flask/app.py:1761]
Traceback (most recent call last):
  File "/home/how_r_u/.local/lib/python3.6/site-packages/flask/app.py", line 2292, in wsgi_app
    response = self.full_dispatch_request()
  File "/home/how_r_u/.local/lib/python3.6/site-packages/flask/app.py", line 1815, in full_dispatch_request
    rv = self.handle_user_exception(e)
  File "/home/how_r_u/.local/lib/python3.6/site-packages/flask/app.py", line 1718, in handle_user_exception
    reraise(exc_type, exc_value, tb)
  File "/home/how_r_u/.local/lib/python3.6/site-packages/flask/_compat.py", line 35, in reraise
    raise value
  File "/home/how_r_u/.local/lib/python3.6/site-packages/flask/app.py", line 1813, in full_dispatch_request
    rv = self.dispatch_request()
  File "/home/how_r_u/.local/lib/python3.6/site-packages/flask/app.py", line 1799, in dispatch_request
    return self.view_functions[rule.endpoint](**req.view_args)
  File "/home/how_r_u/.local/lib/python3.6/site-packages/flask_login/utils.py", line 261, in decorated_view
    return func(*args, **kwargs)
  File "/home/how_r_u/Desktop/mega_book/app/routes.py", line 90, in user
    next_url = url_for("user", page=posts.next_num) if posts.has_next else None
  File "/home/how_r_u/.local/lib/python3.6/site-packages/flask/helpers.py", line 356, in url_for
    return appctx.app.handle_url_build_error(error, endpoint, values)
  File "/home/how_r_u/.local/lib/python3.6/site-packages/flask/app.py", line 2061, in handle_url_build_error
    reraise(exc_type, exc_value, tb)
  File "/home/how_r_u/.local/lib/python3.6/site-packages/flask/_compat.py", line 35, in reraise
    raise value
  File "/home/how_r_u/.local/lib/python3.6/site-packages/flask/helpers.py", line 345, in url_for
    force_external=external)
  File "/home/how_r_u/.local/lib/python3.6/site-packages/werkzeug/routing.py", line 1776, in build
    raise BuildError(endpoint, values, method, self)
werkzeug.routing.BuildError: Could not build url for endpoint 'user' with values ['page']. Did you forget to specify values ['username']?
2019-06-25 15:08:52,166 INFO: Microblog startup [in /home/how_r_u/Desktop/mega_book/app/__init__.py:53]
2019-06-25 15:12:39,402 INFO: Microblog startup [in /home/how_r_u/Desktop/mega_book/app/__init__.py:53]
2019-06-25 15:24:06,413 INFO: Microblog startup [in /home/how_r_u/Desktop/mega_book/app/__init__.py:56]
2019-06-25 15:29:33,877 INFO: Microblog startup [in /home/how_r_u/Desktop/mega_book/app/__init__.py:56]
